<?xml version='1.0' encoding='utf-8'?>
<robot xmlns:xacro="http://www.ros.org/wiki/xacro">
    
    <xacro:macro name="base_visual" params="">
        <visual>
            <origin xyz="${BASE_VISUAL['position']}" rpy="${BASE_VISUAL['orientation']}"/>
            <geometry>
                <!--mesh filename="file://$(find ${description_pkg})/meshes/link_0.stl"/-->
                <box size="${BASE_VISUAL['size']}"/>
            </geometry>
            <material name="link_color">
                <color rgba="${BASE_VISUAL['color']}"/>
            </material>
        </visual>
    </xacro:macro>


    <!-- Pure Visual (No dynamics) -->
    <xacro:macro name="manipulator_visual" params="">
        <link name="odom"/>
        <link name="base_link">
            <origin xyz="0 0 0" rpy="0 0 0"/>
        </link>
        
        <link name="left_wheel"/>
        <link name="right_wheel"/>

        <link name="imu">
            <origin xyz="0 0 0" rpy="0 0 0"/>
        </link>

        <link name="tilt_link">
            <origin xyz="0 0 0" rpy="0 0 0"/>
        </link>

        <!-- <link name="end_effector"/> -->

        <joint name="base_offset" type="fixed">
            <parent link="odom"/>
            <child link="base_link"/>
            <origin xyz="0 0 0.05775" rpy="0 0 0"/>
        </joint>

        <joint name="left_wheel" type="revolute">
            <parent link="base_link"/>
            <child link="left_wheel"/>
            <origin xyz="0 0.08125 -0.024" rpy="0 0 0"/>
            <axis xyz="0 1 0"/>
            <limit 
                lower="-3.1459" 
                upper="3.1459" 
                velocity="1000.0" 
                effort="1000.0"/>
        </joint>

        <joint name="right_wheel" type="revolute">
            <parent link="base_link"/>
            <child link="right_wheel"/>
            <origin xyz="0 -0.08125 -0.024" rpy="0 0 0"/>
            <axis xyz="0 1 0"/>
            <limit 
                lower="-3.1459" 
                upper="3.1459" 
                velocity="1000.0" 
                effort="1000.0"/>
        </joint>

        <joint name="tilt" type="fixed">
            <parent link="base_link"/>
            <child link="tilt_link"/>
            <origin xyz="0 0 0" rpy="0 -0.0698132 0"/>
        </joint>

        <joint name="imu" type="fixed">
            <parent link="tilt_link"/>
            <child link="imu"/>
            <origin xyz="0.097 0 0" rpy="0 0 0"/>
        </joint>



        <!-- <joint name="end_effector_offset" type="fixed">
            <parent link="link_demo"/>
            <child link="end_effector"/>
            <origin xyz="0 0 1.0" rpy="0 ${-3.14159/2} 0"/> 
            <axis xyz="0 0 1"/>
            <limit 
                lower="-3.1459" 
                upper="3.1459" 
                velocity="1000.0" 
                effort="1000.0"/>
        </joint> -->
    </xacro:macro>
</robot>
